错误处理



抛出异常的方式：



使用throws关键字来抛出异常



func hasError() throws{



}



捕获异常的方式：

 

do{
  try hasError()

 //没有异常，继续执行，有异常走 catch块

}catch errorName1 {

  //对异常进行处理

  //与第一个异常匹配即走该catch块

}catch errorName2{

  //与该异常匹配即走该catch块

}